2024-02-13 16:12:14,911 INFO    StreamThr :22328 [internal.py:wandb_internal():86] W&B internal server running at pid: 22328, started at: 2024-02-13 16:12:14.911942
2024-02-13 16:12:14,913 DEBUG   HandlerThread:22328 [handler.py:handle_request():146] handle_request: status
2024-02-13 16:12:14,915 INFO    WriterThread:22328 [datastore.py:open_for_write():87] open: C:\workspace\udacity_training\wandb\run-20240213_161214-pfj595og\run-pfj595og.wandb
2024-02-13 16:12:14,918 DEBUG   SenderThread:22328 [sender.py:send():382] send: header
2024-02-13 16:12:14,918 DEBUG   SenderThread:22328 [sender.py:send():382] send: run
2024-02-13 16:12:18,517 INFO    SenderThread:22328 [retry.py:__call__():172] Retry attempt failed:
Traceback (most recent call last):
  File "C:\Anaconda\envs\udaproject\lib\site-packages\urllib3\connection.py", line 198, in _new_conn
    sock = connection.create_connection(
  File "C:\Anaconda\envs\udaproject\lib\site-packages\urllib3\util\connection.py", line 60, in create_connection
    for res in socket.getaddrinfo(host, port, family, socket.SOCK_STREAM):
  File "C:\Anaconda\envs\udaproject\lib\socket.py", line 918, in getaddrinfo
    for res in _socket.getaddrinfo(host, port, family, type, proto, flags):
socket.gaierror: [Errno 11001] getaddrinfo failed

The above exception was the direct cause of the following exception:

Traceback (most recent call last):
  File "C:\Anaconda\envs\udaproject\lib\site-packages\urllib3\connectionpool.py", line 793, in urlopen
    response = self._make_request(
  File "C:\Anaconda\envs\udaproject\lib\site-packages\urllib3\connectionpool.py", line 491, in _make_request
    raise new_e
  File "C:\Anaconda\envs\udaproject\lib\site-packages\urllib3\connectionpool.py", line 467, in _make_request
    self._validate_conn(conn)
  File "C:\Anaconda\envs\udaproject\lib\site-packages\urllib3\connectionpool.py", line 1099, in _validate_conn
    conn.connect()
  File "C:\Anaconda\envs\udaproject\lib\site-packages\urllib3\connection.py", line 616, in connect
    self.sock = sock = self._new_conn()
  File "C:\Anaconda\envs\udaproject\lib\site-packages\urllib3\connection.py", line 205, in _new_conn
    raise NameResolutionError(self.host, self, e) from e
urllib3.exceptions.NameResolutionError: <urllib3.connection.HTTPSConnection object at 0x00000243C7949070>: Failed to resolve 'api.wandb.ai' ([Errno 11001] getaddrinfo failed)

The above exception was the direct cause of the following exception:

Traceback (most recent call last):
  File "C:\Anaconda\envs\udaproject\lib\site-packages\requests\adapters.py", line 486, in send
    resp = conn.urlopen(
  File "C:\Anaconda\envs\udaproject\lib\site-packages\urllib3\connectionpool.py", line 847, in urlopen
    retries = retries.increment(
  File "C:\Anaconda\envs\udaproject\lib\site-packages\urllib3\util\retry.py", line 515, in increment
    raise MaxRetryError(_pool, url, reason) from reason  # type: ignore[arg-type]
urllib3.exceptions.MaxRetryError: HTTPSConnectionPool(host='api.wandb.ai', port=443): Max retries exceeded with url: /graphql (Caused by NameResolutionError("<urllib3.connection.HTTPSConnection object at 0x00000243C7949070>: Failed to resolve 'api.wandb.ai' ([Errno 11001] getaddrinfo failed)"))

During handling of the above exception, another exception occurred:

Traceback (most recent call last):
  File "C:\Anaconda\envs\udaproject\lib\site-packages\wandb\sdk\lib\retry.py", line 131, in __call__
    result = self._call_fn(*args, **kwargs)
  File "C:\Anaconda\envs\udaproject\lib\site-packages\wandb\sdk\internal\internal_api.py", line 369, in execute
    return self.client.execute(*args, **kwargs)  # type: ignore
  File "C:\Anaconda\envs\udaproject\lib\site-packages\wandb\vendor\gql-0.2.0\wandb_gql\client.py", line 52, in execute
    result = self._get_result(document, *args, **kwargs)
  File "C:\Anaconda\envs\udaproject\lib\site-packages\wandb\vendor\gql-0.2.0\wandb_gql\client.py", line 60, in _get_result
    return self.transport.execute(document, *args, **kwargs)
  File "C:\Anaconda\envs\udaproject\lib\site-packages\wandb\sdk\lib\gql_request.py", line 58, in execute
    request = self.session.post(self.url, **post_args)
  File "C:\Anaconda\envs\udaproject\lib\site-packages\requests\sessions.py", line 637, in post
    return self.request("POST", url, data=data, json=json, **kwargs)
  File "C:\Anaconda\envs\udaproject\lib\site-packages\requests\sessions.py", line 589, in request
    resp = self.send(prep, **send_kwargs)
  File "C:\Anaconda\envs\udaproject\lib\site-packages\requests\sessions.py", line 703, in send
    r = adapter.send(request, **kwargs)
  File "C:\Anaconda\envs\udaproject\lib\site-packages\requests\adapters.py", line 519, in send
    raise ConnectionError(e, request=request)
requests.exceptions.ConnectionError: HTTPSConnectionPool(host='api.wandb.ai', port=443): Max retries exceeded with url: /graphql (Caused by NameResolutionError("<urllib3.connection.HTTPSConnection object at 0x00000243C7949070>: Failed to resolve 'api.wandb.ai' ([Errno 11001] getaddrinfo failed)"))
2024-02-13 16:12:19,953 DEBUG   HandlerThread:22328 [handler.py:handle_request():146] handle_request: keepalive
2024-02-13 16:12:24,992 DEBUG   HandlerThread:22328 [handler.py:handle_request():146] handle_request: keepalive
2024-02-13 16:12:30,038 DEBUG   HandlerThread:22328 [handler.py:handle_request():146] handle_request: keepalive
2024-02-13 16:12:35,058 DEBUG   HandlerThread:22328 [handler.py:handle_request():146] handle_request: keepalive
2024-02-13 16:12:40,094 DEBUG   HandlerThread:22328 [handler.py:handle_request():146] handle_request: keepalive
2024-02-13 16:12:45,121 DEBUG   HandlerThread:22328 [handler.py:handle_request():146] handle_request: keepalive
2024-02-13 16:12:50,169 DEBUG   HandlerThread:22328 [handler.py:handle_request():146] handle_request: keepalive
2024-02-13 16:12:55,221 DEBUG   HandlerThread:22328 [handler.py:handle_request():146] handle_request: keepalive
2024-02-13 16:13:00,259 DEBUG   HandlerThread:22328 [handler.py:handle_request():146] handle_request: keepalive
2024-02-13 16:13:05,289 DEBUG   HandlerThread:22328 [handler.py:handle_request():146] handle_request: keepalive
2024-02-13 16:13:10,361 DEBUG   HandlerThread:22328 [handler.py:handle_request():146] handle_request: shutdown
2024-02-13 16:13:10,361 INFO    HandlerThread:22328 [handler.py:finish():869] shutting down handler
2024-02-13 16:13:11,328 INFO    WriterThread:22328 [datastore.py:close():296] close: C:\workspace\udacity_training\wandb\run-20240213_161214-pfj595og\run-pfj595og.wandb
